# 28.1 오류처리란

**오류처리** : 프로그램이 오류를 일으켰을 때 이것을 감지하고 회복시키는 일련의 과정

프로그램에서 모든 기능이 우리가 원하는대로 100% 정확히 동작한다는 보장은 없다. 특히나 전달받아야 하는 값이 까다롭거나 데이터를 가공하는 데 소비하는 자원이 많은 경우 오류가 발생할 확률이 높아진다. 이런 가능성이 있는 기능을 구현할 때는 오류가 발생할 수 있음을 항상 고려해야 한다.

오류처리 기능을 통해 프로그램 자체적으로 오류를 해결할 수도 있고, 사용자와 상호작용을 통해 오류를 어떤 방향으로 풀어나갈지 제어할 수도 있다. 다만 스위프트의 오류처리 기능을 통해 시스템에서 발생한 오류를 처리할 수 있는 것은 아니다.



# 28.2 오류의 표현

스위프트에서 오류는 Error라는 프로토콜을 준수하는 타입의 값을 통해 표현된다. Error 프로토콜은 사실상 요구사항이 없는 빈 프로토콜일 뿐이지만, 오류를 표현하기 위한 타입(주로 열거형)은 이 프로토콜을 채택한다. 

스위프트의 열거형은 오류의 종류를 나타내기에 아주 적합한 기능이다. 연관 값을 통해 오류에 관한 부가 정보를 제공할 수도 있다.  열거형을 통해 오류의 종류를 표현하는 것이 가장 일반적이며 편리하다. 

오류의 종류를 미리 예상한 다음, 오류 때문에 다음에 행할 동작이 정상적으로 진행되지 않을 때라면 **오류를 던져**주면 된다. 오류를 던져줄 떄는 **throw** 구문을 사용한다.



# 28.3 오류 포착 및 처리

오류를 던질 수 있지만 오류가 던져지는 것에 대비하여 던져진 오류를 처리하기 위한 코드도 작성해야 한다. 예를 들어 던져진 오류가 무엇인지 판단하여 다시 문제를 해결한다든지, 다른 방법으로 문제 해결을 시도해 본다든지, 오류를 알리고 사용자에게 선택 권한을 넘겨주어 다음에 어떤 동작을 하게 할 것인지 결정하도록 유도하는 등의 코드를 작성해야 한다. 스위프트에는 오류를 처리하기 위한 네 가지 방법이 있다.

- 함수에서 발생한 오류를 해당 함수를 호출한 코드에 알리는 방법

- do-catch 구문을 이용하여 오류를 처리하는 방법

- 옵셔널 값으로 오류를 처리하는 방법

- 오류가 발생하지 않을 것이라고 확신하는 방법

  

#### 28.3.1 함수에서 발생한 오류 알리기

먼저 함수에서 발생한 오류를 해당 함수를 호출한 코드에 알리는 방법이다. 함수가 오류를 던지면 프로그램의 흐름이 바뀔 가능성이 매우 크다. 그러므로 어디서 오류를 던지고 받을 것인가 결정하는 것은 매우 중요하다. try 키워드로 던져진 오류를 받을 수 있다. try 또는 try?, try! 등으로 표현할 수 있다.

함수 메서드, 이니셜라이저의 매개변수 뒤에 throws 키워드를 사용하면 해당 함수, 메서드, 이니셜라이저는 오류를 던질 수 있다. 일반적으로 func cannotThrowErrors() -> String처럼 표현하던 것에 func canThrowErrors() throws -> String처럼 throws 키워드를 명시해주면 오류를 던질 수 있다. 이런 함수는 호출했을 떄, 동작 도중 오류가 발생하면 자신을 호출한 코드에 오류를 던져서 오류를 알릴 수 있다. 

> throws는 함수나 메서드의 자체 타입에도 영향을 미친다. 즉, throws 함수나 메서드는 캍은 이름의 throws가 명시되지 않는 함수나 메서드와 구분된다. 또, throws를 포함한 함수, 메서드, 이니셜라이저는 일반 함수, 메서드, 이니셜라이저로 재정의할 수 없다. 반대로 일반 함수, 메서드, 이니셜라이저는 throws함수, 메서드, 이니셜라이저로 재정의할 수 있다.

#### 28.3.2 do-catch 구문을 이용하여 오류처리

함수, 메서드, 이니셜라이저 등에서 오류를 던져주면 오류 발생을 전달받은 코드 블록은 **do-catch 구문**을 사용하여 오류를 처리해주어야 한다. do 절 내부의 코드에서 오류를 던지면 catch 절에서 오류를 전달받아 적절히 처리해주면 된다. do-catch 구문은 보통 다음처럼 표현한다.

```swift
do {
  try 오류발생가능코드
  오류가 발생하지 않으면 실행할 코드
} catch 오류패턴1 {
  처리코드
} catch 오류패턴2 where 추가조건 {
  처리코드
}
```

catch 절에서 catch 키워드 뒤에 처리할 오류의 종류를 써준다. 만약 catch 뒤에 오류의 종류를 명시하지 않고 코드 블록을 생성하면 블록 내부에 암시적으로 error라는 이름의 지역 상수가 오류의 내용으로 들어온다. 

#### 28.3.3 옵셔널 값으로 오류처리

try?를 사용하여 옵셔널 값으로 변환하여 오류를 처리할 수도 있다. try? 표현을 통해 동작하던 코드가 오류를 던지면 그 코드의 반환 값은 nil이 된다. 함수의 반환 타입이 정해져 있어도 try? 표현을 사용하면 반환 타입이 옵셔널로 바뀐다. 

#### 28.3.4 오류가 발생하지 않을 것이라고 확신하는 방법

오류가 절대로 발생하지 않을 것이라고 확신할 수 있는 상황이라면 오류가 발생하지 않을 것이라는 전제하에 try! 표현을 사용할 수 있다. 이 표현은 다른 느낌표 표현과 마찬가지로 실제 오류가 발생하면 런타임 오류가 발생하여 프로그램이 강제로 종료된다. 

#### 28.3.5 다시던지기

함수나 메서드는 rethrows 키워드를 사용하여 자신의 매개변수로 전달받은 함수가 오류를 던진다는 것을 나타낼 수 있다. **rethrows** 키워드를 사용하여 **다시던지기**가 가능하게 하려면 최소 하나 이상의 오류 발생 가능한 함수를 매개변수로 전달받아야 한다. 다음코드는 오류의 다시던지기이다. 

```swift
// 오류를 던지는 함수
func someThrowingFunction() throws {
  enum SomeError: Error {
    case justSomeError
  }
  
  throw SomeError.justSomeError
}

// 다시던지기 함수
func someFunction(callback: () throws -> Void) rethrows {
  try callback() // 다시던지기 함수는 오류를 다시 던질 뿐 따로 처리하지는 않는다.
}

do {
  try someFunction(callback: someThrowingFunction)
} catch {
  print(error)
}
// justSomeError
```

다시던지기 함수 또는 메서드는 기본적으로 스스로 오류를 던지지 못한다. 즉, 자신 내부에 직접적으로 throw 구문을 사용할 수 없다. 그러나 catch 절 내부에서는 throw 구문을 작성할 수 있다. 다시던지기 함수나 메서드가 오류를 던지는 함수를 do-catch 구문 내부에서 호출하고 catch 절 내부에서 다른 오류를 던짐으로써 오류를 던지는 함수에서 발생한 오류를 제어할 수 있다. 다시던지기 내부에 catch 절에서는 다시던지기 함수의 매개변수로 전달받은 오류던지기 함수만 호출하고 결과로 던져진 오류만 제어할 수 있다.

부모클래스의 rethrows 메서드는 자식클래스에서 throws 메서드로 재정의할 수 없다. 그러나 부모클래스의 throws 메서드는 자식클래스에서 rethrows 메서드로 재정의할 수 있다. 그리고 만약 프로토콜 요구사항 중에 다시던지기 메서드가 있다면, 던지기 메서드를 구현한다고 해서 요구사항을 충족시킬 수는 없다. 그러나 프로토콜 요구사항 중에 던지기 메서드가 있다면 다시던지기 메서드를 구현해서 요구사항을 충족시킬 수 있다. 

#### 28.3.6 후처리 defer

defer 구문을 사용하여 현재 코드 블록을 나가기 전에 꼭 실행해야 하는 코드를 작성해줄 수 있다. 즉, defer 구문은 코드가 블록을 어떤 식으로 빠져나가든 간에 꼭 실행해야 하는 마무리 작업을 할 수 있도록 도와준다. 그리고 블록을 빠져나가기 전에 무조건 실행되는 것을 보장한다는 뜻이다. 

> defer 구문과 오류처리
>
> > defer 구문은 꼭 오류처리 상황뿐만 아니라 함수, 메서드, 반복문, 조건문 등등 보통의 코드 블록 어디에서든 사용할 수 있다. 

defer 구문은 현재 코드 범위를 벗어나기 전까지 실행을 미루고 있다가 프로그램 실행 흐름이 코드 범위를 벗어나기 직전 실행된다. defer 구문 내부에는 break, return 등과 같이 구문을 빠져나갈 수 있는 코드 또는 오류를 던지는 코드는 작성하며 안된다. 여러 개의 defer 구문이 하나의 블록 내부에 속해 있다면 맨 마지막에 작성된 구문부터 역순으로 실행된다. 

